Workbook

Sheet Проверка данных
A1: Менеджер | B1: Дата первой встречи | C1: Компания-клиент | D1: Статус клиента | E1: E-mail | F1: Продукт | G1: Канал | H1: Коммерческое предложение | I1: Статус сделки | J1: Скидка | K1: Факт оплаты | L1: Дата оплаты | M1: Причина отказа
A2: Ягренев | B2: 43467 | C2: МЕГАПОЛИС, торговая компания | D2: Постоянный | E2: =VLOOKUP(C2,Контакты!A:B,2,0) -> petrovamn@MEGAPOLIS.ru | F2: Бумажные книги | G2: Холодный звонок | H2: 1915117 | I2: Торг/согласование | J2: 95755.85 | K2: =H2-J2 -> 1819361.1
A3: Ягренев | B3: 43471 | C3: Сахалин Энерджи | D3: Постоянный | E3: =VLOOKUP(C3,Контакты!A:B,2,0) -> or@Sakhalin.ru | F3: Бумажные книги | G3: Холодный звонок | H3: 939129 | I3: КП
A4: Ягренев | B4: 43477 | C4: Росатом, госкорпорация | D4: Постоянный | E4: =VLOOKUP(C4,Контакты!A:B,2,0) -> info@Rosatom.ru | F4: ЭБ | G4: Работа с постоянными | H4: 1648102 | I4: Закрыта | K4: 1648102 | L4: 43498
A5: Лоскутников | B5: 43479 | C5: Ашан | D5: Постоянный | E5: =VLOOKUP(C5,Контакты!A:B,2,0) -> petrovamn@Ashan.ru | F5: Бумажные книги | G5: Работа с постоянными | H5: 962636 | I5: В оплате
A6: Лоскутников | B6: 43484 | C6: Система, АФК | D6: Постоянный | E6: =VLOOKUP(C6,Контакты!A:B,2,0) -> sales@AFK.ru | F6: Записи тренингов | G6: Выставка | H6: 1161335 | I6: В оплате
A7: Ягренев | B7: 43488 | C7: Русал, объединенная компания | D7: Постоянный | E7: =VLOOKUP(C7,Контакты!A:B,2,0) -> al@Rusal.ru | F7: Онлайн-курс | G7: Выставка | H7: 1073347 | I7: В оплате
A8: Лоскутников | B8: 43493 | C8: Сахалин Энерджи | D8: Постоянный | E8: =VLOOKUP(C8,Контакты!A:B,2,0) -> or@Sakhalin.ru | F8: Тренинги | G8: Сайт | H8: 6025810 | I8: Отказ | M8: Нет потребности
A9: Ягренев | B9: 43494 | C9: Аэрофлот | D9: Постоянный | E9: =VLOOKUP(C9,Контакты!A:B,2,0) -> sgAeroflot.ru | F9: Онлайн-курс | G9: Холодный звонок | H9: 929108 | I9: Отказ | M9: Нет бюджета
A10: Лукьянова | B10: 43497 | C10: Аэрофлот | D10: Постоянный | E10: =VLOOKUP(C10,Контакты!A:B,2,0) -> sgAeroflot.ru | F10: Тренинги | G10: Работа с постоянными | H10: 5400127 | I10: Закрыта | K10: 5400127 | L10: 43516
A11: Лукьянова | B11: 43501 | C11: ЛУКОЙЛ | D11: Постоянный | E11: =VLOOKUP(C11,Контакты!A:B,2,0) -> lebedev@LUKOJL.ru | F11: Тренинги | G11: Работа с постоянными | H11: 4754707 | I11: В оплате
A12: Головаха | B12: 43524 | C12: Лента (сеть гипермаркетов) | D12: Новый | E12: =VLOOKUP(C12,Контакты!A:B,2,0) -> kuznetsova@Lenta.ru | F12: Онлайн-курс | G12: Сайт | H12: 275688 | I12: Торг/согласование | J12: 13784.4
A13: Лоскутников | B13: 43552 | C13: Сбербанк России | D13: Постоянный | E13: =VLOOKUP(C13,Контакты!A:B,2,0) -> kn@Sberbank.ru | F13: Электронная библиотека | G13: Работа с постоянными | H13: 5757530 | I13: КП
A14: Лукьянова | B14: 43556 | C14: Транснефть, АК | D14: Новый | E14: =VLOOKUP(C14,Контакты!A:B,2,0) -> ey@Transneft.ru | F14: Тренинги | G14: Выставка | H14: 3437765 | I14: Торг/согласование
A15: Лоскутников | B15: 43566 | C15: Роснефть, нефтяная компания | D15: Постоянный | E15: =VLOOKUP(C15,Контакты!A:B,2,0) -> pavlov@Rosneft.ru | F15: Записи тренингов | G15: Другой | H15: 1159999 | I15: В оплате
A16: Лоскутников | B16: 43567 | C16: РусГидро | D16: Постоянный | E16: =VLOOKUP(C16,Контакты!A:B,2,0) -> semenov@RusGidro.ru | F16: Онлайн-курс | G16: Холодный звонок | H16: 2001156 | I16: Торг/согласование
A17: Ягренев | B17: 43567 | C17: Газпром | D17: Постоянный | E17: =VLOOKUP(C17,Контакты!A:B,2,0) -> kozlov@Gazprom.ru | F17: Бумажные книги | G17: Работа с постоянными | H17: 1479938 | I17: Торг/согласование
A18: Ягренев | B18: 43570 | C18: НОВАТЭК | D18: Постоянный | E18: =VLOOKUP(C18,Контакты!A:B,2,0) -> ceo@NOVATEK.ru | F18: Тренинги | G18: Сайт | H18: 576223 | I18: КП
A19: Ягренев | B19: 43588 | C19: Российский Сельскохозяйственный банк | D19: Постоянный | E19: =VLOOKUP(C19,Контакты!A:B,2,0) -> pukhov@RSB.ru | F19: Электронная библиотека | G19: Холодный звонок | H19: 289773 | I19: Торг/согласование | J19: 8693.19
A20: Ягренев | B20: 43598 | C20: Ашан | D20: Постоянный | E20: =VLOOKUP(C20,Контакты!A:B,2,0) -> petrovamn@Ashan.ru | F20: Электронная библиотека | G20: Работа с постоянными | H20: 5859854 | I20: В оплате
A21: Головаха | B21: 43607 | C21: Российские сети | D21: Новый | E21: =VLOOKUP(C21,Контакты!A:B,2,0) -> smirnov@Rossijskie_seti.ru | F21: Бумажные книги | G21: Выставка | H21: 985377 | I21: В оплате
A22: Лукьянова | B22: 43628 | C22: Объединенная авиастроительная корпорация | D22: Постоянный | E22: =VLOOKUP(C22,Контакты!A:B,2,0) -> uv@Obedinennaya.ru | F22: Записи тренингов | G22: Холодный звонок | H22: 1862733 | I22: КП
A23: Головаха | B23: 43642 | C23: Объединенная авиастроительная корпорация | D23: Постоянный | E23: =VLOOKUP(C23,Контакты!A:B,2,0) -> uv@Obedinennaya.ru | F23: Бумажные книги | G23: Другой | H23: 801952 | I23: Отказ | M23: Нет потребности
A24: Лукьянова | B24: 43644 | C24: Объединенная авиастроительная корпорация | D24: Постоянный | E24: =VLOOKUP(C24,Контакты!A:B,2,0) -> uv@Obedinennaya.ru | F24: Электронная библиотека | G24: Выставка | H24: 7392760 | I24: Закрыта | J24: 221782.8 | K24: 7392760 | L24: 43543
A25: Головаха | B25: 43646 | C25: Дж.Т.И. Россия | D25: Постоянный | E25: =VLOOKUP(C25,Контакты!A:B,2,0) -> ivanov@Dzh.ru | F25: Электронная библиотека | G25: Другой | H25: 3849971 | I25: Торг/согласование
A26: Лоскутников | B26: 43652 | C26: Роснефть, нефтяная компания | D26: Постоянный | E26: =VLOOKUP(C26,Контакты!A:B,2,0) -> pavlov@Rosneft.ru | F26: Тренинги | G26: Выставка | H26: 1403650 | I26: Отказ | M26: Покупают у конкурентов
A27: Ягренев | B27: 43673 | C27: Российские сети | D27: Новый | E27: =VLOOKUP(C27,Контакты!A:B,2,0) -> smirnov@Rossijskie_seti.ru | F27: Тренинги | G27: Сайт | H27: 2497678 | I27: Отказ | M27: Нет бюджета
A28: Ягренев | B28: 43688 | C28: НОВАТЭК | D28: Постоянный | E28: =VLOOKUP(C28,Контакты!A:B,2,0) -> ceo@NOVATEK.ru | F28: Онлайн-курс | G28: Выставка | H28: 1484752 | I28: КП
A29: Лукьянова | B29: 43691 | C29: Северсталь | D29: Постоянный | E29: =VLOOKUP(C29,Контакты!A:B,2,0) -> volkov@Severstal.ru | F29: Тренинги | G29: Работа с постоянными | H29: 5478085 | I29: В оплате | J29: 164342.55
A30: Лоскутников | B30: 43702 | C30: Сбербанк России | D30: Постоянный | E30: =VLOOKUP(C30,Контакты!A:B,2,0) -> kn@Sberbank.ru | F30: Записи тренингов | G30: Сайт | H30: 345315 | I30: Торг/согласование
A31: Лукьянова | B31: 43706 | C31: Дж.Т.И. Россия | D31: Постоянный | E31: =VLOOKUP(C31,Контакты!A:B,2,0) -> ivanov@Dzh.ru | F31: Записи тренингов | G31: Выставка | H31: 1049413 | I31: Торг/согласование
A32: Ягренев | B32: 43716 | C32: Интер РАО | D32: Постоянный | E32: =VLOOKUP(C32,Контакты!A:B,2,0) -> marketing@Inter.ru | F32: Записи тренингов | G32: Сайт | H32: 1667065 | I32: КП
A33: Лоскутников | B33: 43719 | C33: Металлоинвест, холдинговая компания | D33: Постоянный | E33: =VLOOKUP(C33,Контакты!A:B,2,0) -> smirnov@Metalloinvest.ru | F33: Электронная библиотека | G33: Работа с постоянными | H33: 2782323 | I33: КП
A34: Лоскутников | B34: 43719 | C34: СИБУР Холдинг | D34: Постоянный | E34: =VLOOKUP(C34,Контакты!A:B,2,0) -> vinogradov@SIBUR.ru | F34: Электронная библиотека | G34: Выставка | H34: 4435278 | I34: Закрыта | K34: 4435278 | L34: 43748
A35: Головаха | B35: 43722 | C35: Металлоинвест, холдинговая компания | D35: Постоянный | E35: =VLOOKUP(C35,Контакты!A:B,2,0) -> smirnov@Metalloinvest.ru | F35: Онлайн-курс | G35: Работа с постоянными | H35: 3866703 | I35: Отказ | M35: Другое
A36: Ягренев | B36: 43725 | C36: Интер РАО | D36: Новый | E36: =VLOOKUP(C36,Контакты!A:B,2,0) -> marketing@Inter.ru | F36: Бумажные книги | G36: Сайт | H36: 1701791 | I36: Отказ | M36: Другое
A37: Лукьянова | B37: 43731 | C37: Ростех | D37: Новый | E37: =VLOOKUP(C37,Контакты!A:B,2,0) -> iv@Rostekh.ru | F37: Онлайн-курс | G37: Выставка | H37: 3890483 | I37: Торг/согласование
A38: Ягренев | B38: 43735 | C38: ВымпелКом | D38: Новый | E38: =VLOOKUP(C38,Контакты!A:B,2,0) -> vinogradov@VympelKom.ru | F38: Тренинги | G38: Другой | H38: 5875064 | I38: Торг/согласование | J38: 293753.2
A39: Ягренев | B39: 43747 | C39: Сахалин Энерджи | D39: Постоянный | E39: =VLOOKUP(C39,Контакты!A:B,2,0) -> or@Sakhalin.ru | F39: Онлайн-курс | G39: Работа с постоянными | H39: 1806335 | I39: В оплате
A40: Ягренев | B40: 43770 | C40: Русал, объединенная компания | D40: Постоянный | E40: =VLOOKUP(C40,Контакты!A:B,2,0) -> al@Rusal.ru | F40: Бумажные книги | G40: Холодный звонок | H40: 516347 | I40: В оплате
...

Sheet Контакты
A1: Компания | B1: Контакт
A2: МЕГАПОЛИС, торговая компания | B2: petrovamn@MEGAPOLIS.ru
A3: Сахалин Энерджи | B3: or@Sakhalin.ru
A4: Росатом, госкорпорация | B4: info@Rosatom.ru
A5: Ашан | B5: petrovamn@Ashan.ru
A6: Система, АФК | B6: sales@AFK.ru
A7: Русал, объединенная компания | B7: al@Rusal.ru
A8: Аэрофлот | B8: sgAeroflot.ru
A9: ЛУКОЙЛ | B9: lebedev@LUKOJL.ru
A10: Лента (сеть гипермаркетов) | B10: kuznetsova@Lenta.ru
A11: Сбербанк России | B11: kn@Sberbank.ru
A12: Транснефть, АК | B12: ey@Transneft.ru
... A35: Банк ВТБ | B35: pukhov@Bank.ru

Sheet Справочник
A1: Канал
A2: Холодный звонок
A3: Выставка
A4: Работа с постоянными
A5: Выставка
A6: Сайт
A7: Другой
